Workbook
Name Act_Bug: 'LookUp Master'!#REF!
Name Act_CR: 'LookUp Master'!#REF!
Name Act_Risk: 'LookUp Master'!#REF!
Name Act_Task: 'LookUp Master'!#REF!
Name ResourceList: Resources!$A$7:$A$1000
Name Sub_Bug: 'LookUp Master'!#REF!
Name Sub_CR: 'LookUp Master'!#REF!
Name Sub_Risk: 'LookUp Master'!#REF!
Name Sub_Task: 'LookUp Master'!#REF!

Sheet Project Dashboard
A1: OrbitFlow — Project Dashboard | All metrics linked to Work Items
A2: Click Task / Bug / Risk / CR counts to navigate to Work Items filter · EV = SOW Contracted Hrs − Actual Task Effort · SV = Planned End − Max Task/Bug End Date
A4: PROJECT IDENTITY | G4: PLANNED SCHEDULE | J4: ACTUALS (from Work Items) | O4: WORK ITEMS (click to filter) | S4: RAG STATUS
A5: Project ID | B5: Project Name | C5: PM | D5: Account Manager | E5: Project Type | F5: Status | G5: Planned Start | H5: Planned End | I5: SOW Hrs (Contracted) | J5: Actual Start (Min Task/Bug) | K5: Actual End (Max Task/Bug) | L5: Actual Effort (hrs) | M5: EV Hrs (SOW−Actual) | N5: SV Days (Planned−Actual End) | O5: Tasks (Done / Total) | P5: Bugs (Fixed / Total) | Q5: Open Risks | R5: Pending CRs | S5: Schedule RAG | T5: Financial RAG | U5: Overall RAG
A6: =IFERROR(INDEX('Projects Master'!$A:$A,ROW()-1),"") | B6: =IFERROR(VLOOKUP(A6,'Projects Master'!$A:$I,2,0),"") | C6: =IFERROR(VLOOKUP(A6,'Projects Master'!$A:$I,3,0),"") | D6: =IFERROR(VLOOKUP(A6,'Projects Master'!$A:$I,4,0),"") | E6: =IFERROR(VLOOKUP(A6,'Projects Master'!$A:$I,5,0),"") | F6: =IFERROR(VLOOKUP(A6,'Projects Master'!$A:$I,6,0),"") | G6: =IFERROR(VLOOKUP(A6,'Projects Master'!$A:$I,7,0),"") | H6: =IFERROR(VLOOKUP(A6,'Projects Master'!$A:$I,8,0),"") | I6: =IFERROR(VLOOKUP(A6,'Projects Master'!$A:$I,9,0),"") | J6: =_xlfn.LET(_xlpm.t,_xlfn.MINIFS('Work Items'!P:P,'Work Items'!D:D,B6,'Work Items'!A:A,"Task"),_xlpm.b,_xlfn.MINIFS('Work Items'!P:P,'Work Items'!D:D,B6,'Work Items'!A:A,"Bug"),_xlpm.m,IF(AND(_xlpm.t=0,_xlpm.b=0),0,IF(_xlpm.t=0,_xlpm.b,IF(_xlpm.b=0,_xlpm.t,MIN(_xlpm.t,_xlpm.b)))),IF(_xlpm.m=0,G6,_xlpm.m)) | K6: =_xlfn.LET(_xlpm.t,_xlfn.MAXIFS('Work Items'!Q:Q,'Work Items'!D:D,B6,'Work Items'!A:A,"Task"),_xlpm.b,_xlfn.MAXIFS('Work Items'!Q:Q,'Work Items'!D:D,B6,'Work Items'!A:A,"Bug"),_xlpm.m,MAX(_xlpm.t,_xlpm.b),IF(_xlpm.m=0,H6,_xlpm.m)) | L6: =IFERROR(SUMIFS('Work Items'!O:O,'Work Items'!D:D,B6,'Work Items'!A:A,"Task"),0) | M6: =IF(ISNUMBER(I6),I6-L6,"N/A") | N6: =IF(AND(ISNUMBER(H6),K6>0),INT(H6-K6),"TBD") | O6: =TEXT(COUNTIFS('Work Items'!A:A,"Task",'Work Items'!D:D,B6,'Work Items'!L:L,"Completed"),"0")&" / "&TEXT(COUNTIFS('Work Items'!A:A,"Task",'Work Items'!D:D,B6),"0")&" Tasks" | P6: =TEXT(COUNTIFS('Work Items'!A:A,"Bug",'Work Items'!D:D,B6,'Work Items'!L:L,"Fixed"),"0")&" / "&TEXT(COUNTIFS('Work Items'!A:A,"Bug",'Work Items'!D:D,B6),"0")&" Bugs" | Q6: =TEXT(COUNTIFS('Work Items'!A:A,"Risk",'Work Items'!D:D,B6,'Work Items'!L:L,"Open"),"0")&" Open" | R6: =TEXT(COUNTIFS('Work Items'!A:A,"CR",'Work Items'!D:D,B6,'Work Items'!L:L,"Pending Approval"),"0")&" Pending" | S6: =IF(N6="TBD","Yellow",IF(ISNUMBER(N6),IF(N6<0,"Red",IF(N6<14,"Yellow","Green")),"Yellow")) | T6: =IF(NOT(ISNUMBER(M6)),"Yellow",IF(M6<0,"Red",IF(M6/I6<0.05,"Yellow","Green"))) | U6: =IF(OR(S6="Red",T6="Red"),"Red",IF(OR(S6="Yellow",T6="Yellow"),"Yellow","Green"))
A7: =IFERROR(INDEX('Projects Master'!$A:$A,ROW()-1),"") | B7: =IFERROR(VLOOKUP(A7,'Projects Master'!$A:$I,2,0),"") | C7: =IFERROR(VLOOKUP(A7,'Projects Master'!$A:$I,3,0),"") | D7: =IFERROR(VLOOKUP(A7,'Projects Master'!$A:$I,4,0),"") | E7: =IFERROR(VLOOKUP(A7,'Projects Master'!$A:$I,5,0),"") | F7: =IFERROR(VLOOKUP(A7,'Projects Master'!$A:$I,6,0),"") | G7: =IFERROR(VLOOKUP(A7,'Projects Master'!$A:$I,7,0),"") | H7: =IFERROR(VLOOKUP(A7,'Projects Master'!$A:$I,8,0),"") | I7: =IFERROR(VLOOKUP(A7,'Projects Master'!$A:$I,9,0),"") | J7: =_xlfn.LET(_xlpm.t,_xlfn.MINIFS('Work Items'!P:P,'Work Items'!D:D,B7,'Work Items'!A:A,"Task"),_xlpm.b,_xlfn.MINIFS('Work Items'!P:P,'Work Items'!D:D,B7,'Work Items'!A:A,"Bug"),_xlpm.m,IF(AND(_xlpm.t=0,_xlpm.b=0),0,IF(_xlpm.t=0,_xlpm.b,IF(_xlpm.b=0,_xlpm.t,MIN(_xlpm.t,_xlpm.b)))),IF(_xlpm.m=0,G7,_xlpm.m)) | K7: =_xlfn.LET(_xlpm.t,_xlfn.MAXIFS('Work Items'!Q:Q,'Work Items'!D:D,B7,'Work Items'!A:A,"Task"),_xlpm.b,_xlfn.MAXIFS('Work Items'!Q:Q,'Work Items'!D:D,B7,'Work Items'!A:A,"Bug"),_xlpm.m,MAX(_xlpm.t,_xlpm.b),IF(_xlpm.m=0,H7,_xlpm.m)) | L7: =IFERROR(SUMIFS('Work Items'!O:O,'Work Items'!D:D,B7,'Work Items'!A:A,"Task"),0) | M7: =IF(ISNUMBER(I7),I7-L7,"N/A") | N7: =IF(AND(ISNUMBER(H7),K7>0),INT(H7-K7),"TBD") | O7: =TEXT(COUNTIFS('Work Items'!A:A,"Task",'Work Items'!D:D,B7,'Work Items'!L:L,"Completed"),"0")&" / "&TEXT(COUNTIFS('Work Items'!A:A,"Task",'Work Items'!D:D,B7),"0")&" Tasks" | P7: =TEXT(COUNTIFS('Work Items'!A:A,"Bug",'Work Items'!D:D,B7,'Work Items'!L:L,"Fixed"),"0")&" / "&TEXT(COUNTIFS('Work Items'!A:A,"Bug",'Work Items'!D:D,B7),"0")&" Bugs" | Q7: =TEXT(COUNTIFS('Work Items'!A:A,"Risk",'Work Items'!D:D,B7,'Work Items'!L:L,"Open"),"0")&" Open" | R7: =TEXT(COUNTIFS('Work Items'!A:A,"CR",'Work Items'!D:D,B7,'Work Items'!L:L,"Pending Approval"),"0")&" Pending" | S7: =IF(N7="TBD","Yellow",IF(ISNUMBER(N7),IF(N7<0,"Red",IF(N7<14,"Yellow","Green")),"Yellow")) | T7: =IF(NOT(ISNUMBER(M7)),"Yellow",IF(M7<0,"Red",IF(M7/I7<0.05,"Yellow","Green"))) | U7: =IF(OR(S7="Red",T7="Red"),"Red",IF(OR(S7="Yellow",T7="Yellow"),"Yellow","Green"))
A8: =IFERROR(INDEX('Projects Master'!$A:$A,ROW()-1),"") | B8: =IFERROR(VLOOKUP(A8,'Projects Master'!$A:$I,2,0),"") | C8: =IFERROR(VLOOKUP(A8,'Projects Master'!$A:$I,3,0),"") | D8: =IFERROR(VLOOKUP(A8,'Projects Master'!$A:$I,4,0),"") | E8: =IFERROR(VLOOKUP(A8,'Projects Master'!$A:$I,5,0),"") | F8: =IFERROR(VLOOKUP(A8,'Projects Master'!$A:$I,6,0),"") | G8: =IFERROR(VLOOKUP(A8,'Projects Master'!$A:$I,7,0),"") | H8: =IFERROR(VLOOKUP(A8,'Projects Master'!$A:$I,8,0),"") | I8: =IFERROR(VLOOKUP(A8,'Projects Master'!$A:$I,9,0),"") | J8: =_xlfn.LET(_xlpm.t,_xlfn.MINIFS('Work Items'!P:P,'Work Items'!D:D,B8,'Work Items'!A:A,"Task"),_xlpm.b,_xlfn.MINIFS('Work Items'!P:P,'Work Items'!D:D,B8,'Work Items'!A:A,"Bug"),_xlpm.m,IF(AND(_xlpm.t=0,_xlpm.b=0),0,IF(_xlpm.t=0,_xlpm.b,IF(_xlpm.b=0,_xlpm.t,MIN(_xlpm.t,_xlpm.b)))),IF(_xlpm.m=0,G8,_xlpm.m)) | K8: =_xlfn.LET(_xlpm.t,_xlfn.MAXIFS('Work Items'!Q:Q,'Work Items'!D:D,B8,'Work Items'!A:A,"Task"),_xlpm.b,_xlfn.MAXIFS('Work Items'!Q:Q,'Work Items'!D:D,B8,'Work Items'!A:A,"Bug"),_xlpm.m,MAX(_xlpm.t,_xlpm.b),IF(_xlpm.m=0,H8,_xlpm.m)) | L8: =IFERROR(SUMIFS('Work Items'!O:O,'Work Items'!D:D,B8,'Work Items'!A:A,"Task"),0) | M8: =IF(ISNUMBER(I8),I8-L8,"N/A") | N8: =IF(AND(ISNUMBER(H8),K8>0),INT(H8-K8),"TBD") | O8: =TEXT(COUNTIFS('Work Items'!A:A,"Task",'Work Items'!D:D,B8,'Work Items'!L:L,"Completed"),"0")&" / "&TEXT(COUNTIFS('Work Items'!A:A,"Task",'Work Items'!D:D,B8),"0")&" Tasks" | P8: =TEXT(COUNTIFS('Work Items'!A:A,"Bug",'Work Items'!D:D,B8,'Work Items'!L:L,"Fixed"),"0")&" / "&TEXT(COUNTIFS('Work Items'!A:A,"Bug",'Work Items'!D:D,B8),"0")&" Bugs" | Q8: =TEXT(COUNTIFS('Work Items'!A:A,"Risk",'Work Items'!D:D,B8,'Work Items'!L:L,"Open"),"0")&" Open" | R8: =TEXT(COUNTIFS('Work Items'!A:A,"CR",'Work Items'!D:D,B8,'Work Items'!L:L,"Pending Approval"),"0")&" Pending" | S8: =IF(N8="TBD","Yellow",IF(ISNUMBER(N8),IF(N8<0,"Red",IF(N8<14,"Yellow","Green")),"Yellow")) | T8: =IF(NOT(ISNUMBER(M8)),"Yellow",IF(M8<0,"Red",IF(M8/I8<0.05,"Yellow","Green"))) | U8: =IF(OR(S8="Red",T8="Red"),"Red",IF(OR(S8="Yellow",T8="Yellow"),"Yellow","Green"))
A9: =IFERROR(INDEX('Projects Master'!$A:$A,ROW()-1),"") | B9: =IFERROR(VLOOKUP(A9,'Projects Master'!$A:$I,2,0),"") | C9: =IFERROR(VLOOKUP(A9,'Projects Master'!$A:$I,3,0),"") | D9: =IFERROR(VLOOKUP(A9,'Projects Master'!$A:$I,4,0),"") | E9: =IFERROR(VLOOKUP(A9,'Projects Master'!$A:$I,5,0),"") | F9: =IFERROR(VLOOKUP(A9,'Projects Master'!$A:$I,6,0),"") | G9: =IFERROR(VLOOKUP(A9,'Projects Master'!$A:$I,7,0),"") | H9: =IFERROR(VLOOKUP(A9,'Projects Master'!$A:$I,8,0),"") | I9: =IFERROR(VLOOKUP(A9,'Projects Master'!$A:$I,9,0),"") | J9: =_xlfn.LET(_xlpm.t,_xlfn.MINIFS('Work Items'!P:P,'Work Items'!D:D,B9,'Work Items'!A:A,"Task"),_xlpm.b,_xlfn.MINIFS('Work Items'!P:P,'Work Items'!D:D,B9,'Work Items'!A:A,"Bug"),_xlpm.m,IF(AND(_xlpm.t=0,_xlpm.b=0),0,IF(_xlpm.t=0,_xlpm.b,IF(_xlpm.b=0,_xlpm.t,MIN(_xlpm.t,_xlpm.b)))),IF(_xlpm.m=0,G9,_xlpm.m)) | K9: =_xlfn.LET(_xlpm.t,_xlfn.MAXIFS('Work Items'!Q:Q,'Work Items'!D:D,B9,'Work Items'!A:A,"Task"),_xlpm.b,_xlfn.MAXIFS('Work Items'!Q:Q,'Work Items'!D:D,B9,'Work Items'!A:A,"Bug"),_xlpm.m,MAX(_xlpm.t,_xlpm.b),IF(_xlpm.m=0,H9,_xlpm.m)) | L9: =IFERROR(SUMIFS('Work Items'!O:O,'Work Items'!D:D,B9,'Work Items'!A:A,"Task"),0) | M9: =IF(ISNUMBER(I9),I9-L9,"N/A") | N9: =IF(AND(ISNUMBER(H9),K9>0),INT(H9-K9),"TBD") | O9: =TEXT(COUNTIFS('Work Items'!A:A,"Task",'Work Items'!D:D,B9,'Work Items'!L:L,"Completed"),"0")&" / "&TEXT(COUNTIFS('Work Items'!A:A,"Task",'Work Items'!D:D,B9),"0")&" Tasks" | P9: =TEXT(COUNTIFS('Work Items'!A:A,"Bug",'Work Items'!D:D,B9,'Work Items'!L:L,"Fixed"),"0")&" / "&TEXT(COUNTIFS('Work Items'!A:A,"Bug",'Work Items'!D:D,B9),"0")&" Bugs" | Q9: =TEXT(COUNTIFS('Work Items'!A:A,"Risk",'Work Items'!D:D,B9,'Work Items'!L:L,"Open"),"0")&" Open" | R9: =TEXT(COUNTIFS('Work Items'!A:A,"CR",'Work Items'!D:D,B9,'Work Items'!L:L,"Pending Approval"),"0")&" Pending" | S9: =IF(N9="TBD","Yellow",IF(ISNUMBER(N9),IF(N9<0,"Red",IF(N9<14,"Yellow","Green")),"Yellow")) | T9: =IF(NOT(ISNUMBER(M9)),"Yellow",IF(M9<0,"Red",IF(M9/I9<0.05,"Yellow","Green"))) | U9: =IF(OR(S9="Red",T9="Red"),"Red",IF(OR(S9="Yellow",T9="Yellow"),"Yellow","Green"))
A10: =IFERROR(INDEX('Projects Master'!$A:$A,ROW()-1),"") | B10: =IFERROR(VLOOKUP(A10,'Projects Master'!$A:$I,2,0),"") | C10: =IFERROR(VLOOKUP(A10,'Projects Master'!$A:$I,3,0),"") | D10: =IFERROR(VLOOKUP(A10,'Projects Master'!$A:$I,4,0),"") | E10: =IFERROR(VLOOKUP(A10,'Projects Master'!$A:$I,5,0),"") | F10: =IFERROR(VLOOKUP(A10,'Projects Master'!$A:$I,6,0),"") | G10: =IFERROR(VLOOKUP(A10,'Projects Master'!$A:$I,7,0),"") | H10: =IFERROR(VLOOKUP(A10,'Projects Master'!$A:$I,8,0),"") | I10: =IFERROR(VLOOKUP(A10,'Projects Master'!$A:$I,9,0),"") | J10: =_xlfn.LET(_xlpm.t,_xlfn.MINIFS('Work Items'!P:P,'Work Items'!D:D,B10,'Work Items'!A:A,"Task"),_xlpm.b,_xlfn.MINIFS('Work Items'!P:P,'Work Items'!D:D,B10,'Work Items'!A:A,"Bug"),_xlpm.m,IF(AND(_xlpm.t=0,_xlpm.b=0),0,IF(_xlpm.t=0,_xlpm.b,IF(_xlpm.b=0,_xlpm.t,MIN(_xlpm.t,_xlpm.b)))),IF(_xlpm.m=0,G10,_xlpm.m)) | K10: =_xlfn.LET(_xlpm.t,_xlfn.MAXIFS('Work Items'!Q:Q,'Work Items'!D:D,B10,'Work Items'!A:A,"Task"),_xlpm.b,_xlfn.MAXIFS('Work Items'!Q:Q,'Work Items'!D:D,B10,'Work Items'!A:A,"Bug"),_xlpm.m,MAX(_xlpm.t,_xlpm.b),IF(_xlpm.m=0,H10,_xlpm.m)) | L10: =IFERROR(SUMIFS('Work Items'!O:O,'Work Items'!D:D,B10,'Work Items'!A:A,"Task"),0) | M10: =IF(ISNUMBER(I10),I10-L10,"N/A") | N10: =IF(AND(ISNUMBER(H10),K10>0),INT(H10-K10),"TBD") | O10: =TEXT(COUNTIFS('Work Items'!A:A,"Task",'Work Items'!D:D,B10,'Work Items'!L:L,"Completed"),"0")&" / "&TEXT(COUNTIFS('Work Items'!A:A,"Task",'Work Items'!D:D,B10),"0")&" Tasks" | P10: =TEXT(COUNTIFS('Work Items'!A:A,"Bug",'Work Items'!D:D,B10,'Work Items'!L:L,"Fixed"),"0")&" / "&TEXT(COUNTIFS('Work Items'!A:A,"Bug",'Work Items'!D:D,B10),"0")&" Bugs" | Q10: =TEXT(COUNTIFS('Work Items'!A:A,"Risk",'Work Items'!D:D,B10,'Work Items'!L:L,"Open"),"0")&" Open" | R10: =TEXT(COUNTIFS('Work Items'!A:A,"CR",'Work Items'!D:D,B10,'Work Items'!L:L,"Pending Approval"),"0")&" Pending" | S10: =IF(N10="TBD","Yellow",IF(ISNUMBER(N10),IF(N10<0,"Red",IF(N10<14,"Yellow","Green")),"Yellow")) | T10: =IF(NOT(ISNUMBER(M10)),"Yellow",IF(M10<0,"Red",IF(M10/I10<0.05,"Yellow","Green"))) | U10: =IF(OR(S10="Red",T10="Red"),"Red",IF(OR(S10="Yellow",T10="Yellow"),"Yellow","Green"))
A11: =IFERROR(INDEX('Projects Master'!$A:$A,ROW()-1),"") | B11: =IFERROR(VLOOKUP(A11,'Projects Master'!$A:$I,2,0),"") | C11: =IFERROR(VLOOKUP(A11,'Projects Master'!$A:$I,3,0),"") | D11: =IFERROR(VLOOKUP(A11,'Projects Master'!$A:$I,4,0),"") | E11: =IFERROR(VLOOKUP(A11,'Projects Master'!$A:$I,5,0),"") | F11: =IFERROR(VLOOKUP(A11,'Projects Master'!$A:$I,6,0),"") | G11: =IFERROR(VLOOKUP(A11,'Projects Master'!$A:$I,7,0),"") | H11: =IFERROR(VLOOKUP(A11,'Projects Master'!$A:$I,8,0),"") | I11: =IFERROR(VLOOKUP(A11,'Projects Master'!$A:$I,9,0),"") | J11: =_xlfn.LET(_xlpm.t,_xlfn.MINIFS('Work Items'!P:P,'Work Items'!D:D,B11,'Work Items'!A:A,"Task"),_xlpm.b,_xlfn.MINIFS('Work Items'!P:P,'Work Items'!D:D,B11,'Work Items'!A:A,"Bug"),_xlpm.m,IF(AND(_xlpm.t=0,_xlpm.b=0),0,IF(_xlpm.t=0,_xlpm.b,IF(_xlpm.b=0,_xlpm.t,MIN(_xlpm.t,_xlpm.b)))),IF(_xlpm.m=0,G11,_xlpm.m)) | K11: =_xlfn.LET(_xlpm.t,_xlfn.MAXIFS('Work Items'!Q:Q,'Work Items'!D:D,B11,'Work Items'!A:A,"Task"),_xlpm.b,_xlfn.MAXIFS('Work Items'!Q:Q,'Work Items'!D:D,B11,'Work Items'!A:A,"Bug"),_xlpm.m,MAX(_xlpm.t,_xlpm.b),IF(_xlpm.m=0,H11,_xlpm.m)) | L11: =IFERROR(SUMIFS('Work Items'!O:O,'Work Items'!D:D,B11,'Work Items'!A:A,"Task"),0) | M11: =IF(ISNUMBER(I11),I11-L11,"N/A") | N11: =IF(AND(ISNUMBER(H11),K11>0),INT(H11-K11),"TBD") | O11: =TEXT(COUNTIFS('Work Items'!A:A,"Task",'Work Items'!D:D,B11,'Work Items'!L:L,"Completed"),"0")&" / "&TEXT(COUNTIFS('Work Items'!A:A,"Task",'Work Items'!D:D,B11),"0")&" Tasks" | P11: =TEXT(COUNTIFS('Work Items'!A:A,"Bug",'Work Items'!D:D,B11,'Work Items'!L:L,"Fixed"),"0")&" / "&TEXT(COUNTIFS('Work Items'!A:A,"Bug",'Work Items'!D:D,B11),"0")&" Bugs" | Q11: =TEXT(COUNTIFS('Work Items'!A:A,"Risk",'Work Items'!D:D,B11,'Work Items'!L:L,"Open"),"0")&" Open" | R11: =TEXT(COUNTIFS('Work Items'!A:A,"CR",'Work Items'!D:D,B11,'Work Items'!L:L,"Pending Approval"),"0")&" Pending" | S11: =IF(N11="TBD","Yellow",IF(ISNUMBER(N11),IF(N11<0,"Red",IF(N11<14,"Yellow","Green")),"Yellow")) | T11: =IF(NOT(ISNUMBER(M11)),"Yellow",IF(M11<0,"Red",IF(M11/I11<0.05,"Yellow","Green"))) | U11: =IF(OR(S11="Red",T11="Red"),"Red",IF(OR(S11="Yellow",T11="Yellow"),"Yellow","Green"))
A12: =IFERROR(INDEX('Projects Master'!$A:$A,ROW()-1),"") | B12: =IFERROR(VLOOKUP(A12,'Projects Master'!$A:$I,2,0),"") | C12: =IFERROR(VLOOKUP(A12,'Projects Master'!$A:$I,3,0),"") | D12: =IFERROR(VLOOKUP(A12,'Projects Master'!$A:$I,4,0),"") | E12: =IFERROR(VLOOKUP(A12,'Projects Master'!$A:$I,5,0),"") | F12: =IFERROR(VLOOKUP(A12,'Projects Master'!$A:$I,6,0),"") | G12: =IFERROR(VLOOKUP(A12,'Projects Master'!$A:$I,7,0),"") | H12: =IFERROR(VLOOKUP(A12,'Projects Master'!$A:$I,8,0),"") | I12: =IFERROR(VLOOKUP(A12,'Projects Master'!$A:$I,9,0),"") | J12: =_xlfn.LET(_xlpm.t,_xlfn.MINIFS('Work Items'!P:P,'Work Items'!D:D,B12,'Work Items'!A:A,"Task"),_xlpm.b,_xlfn.MINIFS('Work Items'!P:P,'Work Items'!D:D,B12,'Work Items'!A:A,"Bug"),_xlpm.m,IF(AND(_xlpm.t=0,_xlpm.b=0),0,IF(_xlpm.t=0,_xlpm.b,IF(_xlpm.b=0,_xlpm.t,MIN(_xlpm.t,_xlpm.b)))),IF(_xlpm.m=0,G12,_xlpm.m)) | K12: =_xlfn.LET(_xlpm.t,_xlfn.MAXIFS('Work Items'!Q:Q,'Work Items'!D:D,B12,'Work Items'!A:A,"Task"),_xlpm.b,_xlfn.MAXIFS('Work Items'!Q:Q,'Work Items'!D:D,B12,'Work Items'!A:A,"Bug"),_xlpm.m,MAX(_xlpm.t,_xlpm.b),IF(_xlpm.m=0,H12,_xlpm.m)) | L12: =IFERROR(SUMIFS('Work Items'!O:O,'Work Items'!D:D,B12,'Work Items'!A:A,"Task"),0) | M12: =IF(ISNUMBER(I12),I12-L12,"N/A") | N12: =IF(AND(ISNUMBER(H12),K12>0),INT(H12-K12),"TBD") | O12: =TEXT(COUNTIFS('Work Items'!A:A,"Task",'Work Items'!D:D,B12,'Work Items'!L:L,"Completed"),"0")&" / "&TEXT(COUNTIFS('Work Items'!A:A,"Task",'Work Items'!D:D,B12),"0")&" Tasks" | P12: =TEXT(COUNTIFS('Work Items'!A:A,"Bug",'Work Items'!D:D,B12,'Work Items'!L:L,"Fixed"),"0")&" / "&TEXT(COUNTIFS('Work Items'!A:A,"Bug",'Work Items'!D:D,B12),"0")&" Bugs" | Q12: =TEXT(COUNTIFS('Work Items'!A:A,"Risk",'Work Items'!D:D,B12,'Work Items'!L:L,"Open"),"0")&" Open" | R12: =TEXT(COUNTIFS('Work Items'!A:A,"CR",'Work Items'!D:D,B12,'Work Items'!L:L,"Pending Approval"),"0")&" Pending" | S12: =IF(N12="TBD","Yellow",IF(ISNUMBER(N12),IF(N12<0,"Red",IF(N12<14,"Yellow","Green")),"Yellow")) | T12: =IF(NOT(ISNUMBER(M12)),"Yellow",IF(M12<0,"Red",IF(M12/I12<0.05,"Yellow","Green"))) | U12: =IF(OR(S12="Red",T12="Red"),"Red",IF(OR(S12="Yellow",T12="Yellow"),"Yellow","Green"))
A13: =IFERROR(INDEX('Projects Master'!$A:$A,ROW()-1),"") | B13: =IFERROR(VLOOKUP(A13,'Projects Master'!$A:$I,2,0),"") | C13: =IFERROR(VLOOKUP(A13,'Projects Master'!$A:$I,3,0),"") | D13: =IFERROR(VLOOKUP(A13,'Projects Master'!$A:$I,4,0),"") | E13: =IFERROR(VLOOKUP(A13,'Projects Master'!$A:$I,5,0),"") | F13: =IFERROR(VLOOKUP(A13,'Projects Master'!$A:$I,6,0),"") | G13: =IFERROR(VLOOKUP(A13,'Projects Master'!$A:$I,7,0),"") | H13: =IFERROR(VLOOKUP(A13,'Projects Master'!$A:$I,8,0),"") | I13: =IFERROR(VLOOKUP(A13,'Projects Master'!$A:$I,9,0),"") | J13: =_xlfn.LET(_xlpm.t,_xlfn.MINIFS('Work Items'!P:P,'Work Items'!D:D,B13,'Work Items'!A:A,"Task"),_xlpm.b,_xlfn.MINIFS('Work Items'!P:P,'Work Items'!D:D,B13,'Work Items'!A:A,"Bug"),_xlpm.m,IF(AND(_xlpm.t=0,_xlpm.b=0),0,IF(_xlpm.t=0,_xlpm.b,IF(_xlpm.b=0,_xlpm.t,MIN(_xlpm.t,_xlpm.b)))),IF(_xlpm.m=0,G13,_xlpm.m)) | K13: =_xlfn.LET(_xlpm.t,_xlfn.MAXIFS('Work Items'!Q:Q,'Work Items'!D:D,B13,'Work Items'!A:A,"Task"),_xlpm.b,_xlfn.MAXIFS('Work Items'!Q:Q,'Work Items'!D:D,B13,'Work Items'!A:A,"Bug"),_xlpm.m,MAX(_xlpm.t,_xlpm.b),IF(_xlpm.m=0,H13,_xlpm.m)) | L13: =IFERROR(SUMIFS('Work Items'!O:O,'Work Items'!D:D,B13,'Work Items'!A:A,"Task"),0) | M13: =IF(ISNUMBER(I13),I13-L13,"N/A") | N13: =IF(AND(ISNUMBER(H13),K13>0),INT(H13-K13),"TBD") | O13: =TEXT(COUNTIFS('Work Items'!A:A,"Task",'Work Items'!D:D,B13,'Work Items'!L:L,"Completed"),"0")&" / "&TEXT(COUNTIFS('Work Items'!A:A,"Task",'Work Items'!D:D,B13),"0")&" Tasks" | P13: =TEXT(COUNTIFS('Work Items'!A:A,"Bug",'Work Items'!D:D,B13,'Work Items'!L:L,"Fixed"),"0")&" / "&TEXT(COUNTIFS('Work Items'!A:A,"Bug",'Work Items'!D:D,B13),"0")&" Bugs" | Q13: =TEXT(COUNTIFS('Work Items'!A:A,"Risk",'Work Items'!D:D,B13,'Work Items'!L:L,"Open"),"0")&" Open" | R13: =TEXT(COUNTIFS('Work Items'!A:A,"CR",'Work Items'!D:D,B13,'Work Items'!L:L,"Pending Approval"),"0")&" Pending" | S13: =IF(N13="TBD","Yellow",IF(ISNUMBER(N13),IF(N13<0,"Red",IF(N13<14,"Yellow","Green")),"Yellow")) | T13: =IF(NOT(ISNUMBER(M13)),"Yellow",IF(M13<0,"Red",IF(M13/I13<0.05,"Yellow","Green"))) | U13: =IF(OR(S13="Red",T13="Red"),"Red",IF(OR(S13="Yellow",T13="Yellow"),"Yellow","Green"))
A14: =IFERROR(INDEX('Projects Master'!$A:$A,ROW()-1),"") | B14: =IFERROR(VLOOKUP(A14,'Projects Master'!$A:$I,2,0),"") | C14: =IFERROR(VLOOKUP(A14,'Projects Master'!$A:$I,3,0),"") | D14: =IFERROR(VLOOKUP(A14,'Projects Master'!$A:$I,4,0),"") | E14: =IFERROR(VLOOKUP(A14,'Projects Master'!$A:$I,5,0),"") | F14: =IFERROR(VLOOKUP(A14,'Projects Master'!$A:$I,6,0),"") | G14: =IFERROR(VLOOKUP(A14,'Projects Master'!$A:$I,7,0),"") | H14: =IFERROR(VLOOKUP(A14,'Projects Master'!$A:$I,8,0),"") | I14: =IFERROR(VLOOKUP(A14,'Projects Master'!$A:$I,9,0),"") | J14: =_xlfn.LET(_xlpm.t,_xlfn.MINIFS('Work Items'!P:P,'Work Items'!D:D,B14,'Work Items'!A:A,"Task"),_xlpm.b,_xlfn.MINIFS('Work Items'!P:P,'Work Items'!D:D,B14,'Work Items'!A:A,"Bug"),_xlpm.m,IF(AND(_xlpm.t=0,_xlpm.b=0),0,IF(_xlpm.t=0,_xlpm.b,IF(_xlpm.b=0,_xlpm.t,MIN(_xlpm.t,_xlpm.b)))),IF(_xlpm.m=0,G14,_xlpm.m)) | K14: =_xlfn.LET(_xlpm.t,_xlfn.MAXIFS('Work Items'!Q:Q,'Work Items'!D:D,B14,'Work Items'!A:A,"Task"),_xlpm.b,_xlfn.MAXIFS('Work Items'!Q:Q,'Work Items'!D:D,B14,'Work Items'!A:A,"Bug"),_xlpm.m,MAX(_xlpm.t,_xlpm.b),IF(_xlpm.m=0,H14,_xlpm.m)) | L14: =IFERROR(SUMIFS('Work Items'!O:O,'Work Items'!D:D,B14,'Work Items'!A:A,"Task"),0) | M14: =IF(ISNUMBER(I14),I14-L14,"N/A") | N14: =IF(AND(ISNUMBER(H14),K14>0),INT(H14-K14),"TBD") | O14: =TEXT(COUNTIFS('Work Items'!A:A,"Task",'Work Items'!D:D,B14,'Work Items'!L:L,"Completed"),"0")&" / "&TEXT(COUNTIFS('Work Items'!A:A,"Task",'Work Items'!D:D,B14),"0")&" Tasks" | P14: =TEXT(COUNTIFS('Work Items'!A:A,"Bug",'Work Items'!D:D,B14,'Work Items'!L:L,"Fixed"),"0")&" / "&TEXT(COUNTIFS('Work Items'!A:A,"Bug",'Work Items'!D:D,B14),"0")&" Bugs" | Q14: =TEXT(COUNTIFS('Work Items'!A:A,"Risk",'Work Items'!D:D,B14,'Work Items'!L:L,"Open"),"0")&" Open" | R14: =TEXT(COUNTIFS('Work Items'!A:A,"CR",'Work Items'!D:D,B14,'Work Items'!L:L,"Pending Approval"),"0")&" Pending" | S14: =IF(N14="TBD","Yellow",IF(ISNUMBER(N14),IF(N14<0,"Red",IF(N14<14,"Yellow","Green")),"Yellow")) | T14: =IF(NOT(ISNUMBER(M14)),"Yellow",IF(M14<0,"Red",IF(M14/I14<0.05,"Yellow","Green"))) | U14: =IF(OR(S14="Red",T14="Red"),"Red",IF(OR(S14="Yellow",T14="Yellow"),"Yellow","Green"))
A15: =IFERROR(INDEX('Projects Master'!$A:$A,ROW()-1),"") | B15: =IFERROR(VLOOKUP(A15,'Projects Master'!$A:$I,2,0),"") | C15: =IFERROR(VLOOKUP(A15,'Projects Master'!$A:$I,3,0),"") | D15: =IFERROR(VLOOKUP(A15,'Projects Master'!$A:$I,4,0),"") | E15: =IFERROR(VLOOKUP(A15,'Projects Master'!$A:$I,5,0),"") | F15: =IFERROR(VLOOKUP(A15,'Projects Master'!$A:$I,6,0),"") | G15: =IFERROR(VLOOKUP(A15,'Projects Master'!$A:$I,7,0),"") | H15: =IFERROR(VLOOKUP(A15,'Projects Master'!$A:$I,8,0),"") | I15: =IFERROR(VLOOKUP(A15,'Projects Master'!$A:$I,9,0),"") | J15: =_xlfn.LET(_xlpm.t,_xlfn.MINIFS('Work Items'!P:P,'Work Items'!D:D,B15,'Work Items'!A:A,"Task"),_xlpm.b,_xlfn.MINIFS('Work Items'!P:P,'Work Items'!D:D,B15,'Work Items'!A:A,"Bug"),_xlpm.m,IF(AND(_xlpm.t=0,_xlpm.b=0),0,IF(_xlpm.t=0,_xlpm.b,IF(_xlpm.b=0,_xlpm.t,MIN(_xlpm.t,_xlpm.b)))),IF(_xlpm.m=0,G15,_xlpm.m)) | K15: =_xlfn.LET(_xlpm.t,_xlfn.MAXIFS('Work Items'!Q:Q,'Work Items'!D:D,B15,'Work Items'!A:A,"Task"),_xlpm.b,_xlfn.MAXIFS('Work Items'!Q:Q,'Work Items'!D:D,B15,'Work Items'!A:A,"Bug"),_xlpm.m,MAX(_xlpm.t,_xlpm.b),IF(_xlpm.m=0,H15,_xlpm.m)) | L15: =IFERROR(SUMIFS('Work Items'!O:O,'Work Items'!D:D,B15,'Work Items'!A:A,"Task"),0) | M15: =IF(ISNUMBER(I15),I15-L15,"N/A") | N15: =IF(AND(ISNUMBER(H15),K15>0),INT(H15-K15),"TBD") | O15: =TEXT(COUNTIFS('Work Items'!A:A,"Task",'Work Items'!D:D,B15,'Work Items'!L:L,"Completed"),"0")&" / "&TEXT(COUNTIFS('Work Items'!A:A,"Task",'Work Items'!D:D,B15),"0")&" Tasks" | P15: =TEXT(COUNTIFS('Work Items'!A:A,"Bug",'Work Items'!D:D,B15,'Work Items'!L:L,"Fixed"),"0")&" / "&TEXT(COUNTIFS('Work Items'!A:A,"Bug",'Work Items'!D:D,B15),"0")&" Bugs" | Q15: =TEXT(COUNTIFS('Work Items'!A:A,"Risk",'Work Items'!D:D,B15,'Work Items'!L:L,"Open"),"0")&" Open" | R15: =TEXT(COUNTIFS('Work Items'!A:A,"CR",'Work Items'!D:D,B15,'Work Items'!L:L,"Pending Approval"),"0")&" Pending" | S15: =IF(N15="TBD","Yellow",IF(ISNUMBER(N15),IF(N15<0,"Red",IF(N15<14,"Yellow","Green")),"Yellow")) | T15: =IF(NOT(ISNUMBER(M15)),"Yellow",IF(M15<0,"Red",IF(M15/I15<0.05,"Yellow","Green"))) | U15: =IF(OR(S15="Red",T15="Red"),"Red",IF(OR(S15="Yellow",T15="Yellow"),"Yellow","Green"))
A16: =IFERROR(INDEX('Projects Master'!$A:$A,ROW()-1),"") | B16: =IFERROR(VLOOKUP(A16,'Projects Master'!$A:$I,2,0),"") | C16: =IFERROR(VLOOKUP(A16,'Projects Master'!$A:$I,3,0),"") | D16: =IFERROR(VLOOKUP(A16,'Projects Master'!$A:$I,4,0),"") | E16: =IFERROR(VLOOKUP(A16,'Projects Master'!$A:$I,5,0),"") | F16: =IFERROR(VLOOKUP(A16,'Projects Master'!$A:$I,6,0),"") | G16: =IFERROR(VLOOKUP(A16,'Projects Master'!$A:$I,7,0),"") | H16: =IFERROR(VLOOKUP(A16,'Projects Master'!$A:$I,8,0),"") | I16: =IFERROR(VLOOKUP(A16,'Projects Master'!$A:$I,9,0),"") | J16: =_xlfn.LET(_xlpm.t,_xlfn.MINIFS('Work Items'!P:P,'Work Items'!D:D,B16,'Work Items'!A:A,"Task"),_xlpm.b,_xlfn.MINIFS('Work Items'!P:P,'Work Items'!D:D,B16,'Work Items'!A:A,"Bug"),_xlpm.m,IF(AND(_xlpm.t=0,_xlpm.b=0),0,IF(_xlpm.t=0,_xlpm.b,IF(_xlpm.b=0,_xlpm.t,MIN(_xlpm.t,_xlpm.b)))),IF(_xlpm.m=0,G16,_xlpm.m)) | K16: =_xlfn.LET(_xlpm.t,_xlfn.MAXIFS('Work Items'!Q:Q,'Work Items'!D:D,B16,'Work Items'!A:A,"Task"),_xlpm.b,_xlfn.MAXIFS('Work Items'!Q:Q,'Work Items'!D:D,B16,'Work Items'!A:A,"Bug"),_xlpm.m,MAX(_xlpm.t,_xlpm.b),IF(_xlpm.m=0,H16,_xlpm.m)) | L16: =IFERROR(SUMIFS('Work Items'!O:O,'Work Items'!D:D,B16,'Work Items'!A:A,"Task"),0) | M16: =IF(ISNUMBER(I16),I16-L16,"N/A") | N16: =IF(AND(ISNUMBER(H16),K16>0),INT(H16-K16),"TBD") | O16: =TEXT(COUNTIFS('Work Items'!A:A,"Task",'Work Items'!D:D,B16,'Work Items'!L:L,"Completed"),"0")&" / "&TEXT(COUNTIFS('Work Items'!A:A,"Task",'Work Items'!D:D,B16),"0")&" Tasks" | P16: =TEXT(COUNTIFS('Work Items'!A:A,"Bug",'Work Items'!D:D,B16,'Work Items'!L:L,"Fixed"),"0")&" / "&TEXT(COUNTIFS('Work Items'!A:A,"Bug",'Work Items'!D:D,B16),"0")&" Bugs" | Q16: =TEXT(COUNTIFS('Work Items'!A:A,"Risk",'Work Items'!D:D,B16,'Work Items'!L:L,"Open"),"0")&" Open" | R16: =TEXT(COUNTIFS('Work Items'!A:A,"CR",'Work Items'!D:D,B16,'Work Items'!L:L,"Pending Approval"),"0")&" Pending" | S16: =IF(N16="TBD","Yellow",IF(ISNUMBER(N16),IF(N16<0,"Red",IF(N16<14,"Yellow","Green")),"Yellow")) | T16: =IF(NOT(ISNUMBER(M16)),"Yellow",IF(M16<0,"Red",IF(M16/I16<0.05,"Yellow","Green"))) | U16: =IF(OR(S16="Red",T16="Red"),"Red",IF(OR(S16="Yellow",T16="Yellow"),"Yellow","Green"))
A17: =IFERROR(INDEX('Projects Master'!$A:$A,ROW()-1),"") | B17: =IFERROR(VLOOKUP(A17,'Projects Master'!$A:$I,2,0),"") | C17: =IFERROR(VLOOKUP(A17,'Projects Master'!$A:$I,3,0),"") | D17: =IFERROR(VLOOKUP(A17,'Projects Master'!$A:$I,4,0),"") | E17: =IFERROR(VLOOKUP(A17,'Projects Master'!$A:$I,5,0),"") | F17: =IFERROR(VLOOKUP(A17,'Projects Master'!$A:$I,6,0),"") | G17: =IFERROR(VLOOKUP(A17,'Projects Master'!$A:$I,7,0),"") | H17: =IFERROR(VLOOKUP(A17,'Projects Master'!$A:$I,8,0),"") | I17: =IFERROR(VLOOKUP(A17,'Projects Master'!$A:$I,9,0),"") | J17: =_xlfn.LET(_xlpm.t,_xlfn.MINIFS('Work Items'!P:P,'Work Items'!D:D,B17,'Work Items'!A:A,"Task"),_xlpm.b,_xlfn.MINIFS('Work Items'!P:P,'Work Items'!D:D,B17,'Work Items'!A:A,"Bug"),_xlpm.m,IF(AND(_xlpm.t=0,_xlpm.b=0),0,IF(_xlpm.t=0,_xlpm.b,IF(_xlpm.b=0,_xlpm.t,MIN(_xlpm.t,_xlpm.b)))),IF(_xlpm.m=0,G17,_xlpm.m)) | K17: =_xlfn.LET(_xlpm.t,_xlfn.MAXIFS('Work Items'!Q:Q,'Work Items'!D:D,B17,'Work Items'!A:A,"Task"),_xlpm.b,_xlfn.MAXIFS('Work Items'!Q:Q,'Work Items'!D:D,B17,'Work Items'!A:A,"Bug"),_xlpm.m,MAX(_xlpm.t,_xlpm.b),IF(_xlpm.m=0,H17,_xlpm.m)) | L17: =IFERROR(SUMIFS('Work Items'!O:O,'Work Items'!D:D,B17,'Work Items'!A:A,"Task"),0) | M17: =IF(ISNUMBER(I17),I17-L17,"N/A") | N17: =IF(AND(ISNUMBER(H17),K17>0),INT(H17-K17),"TBD") | O17: =TEXT(COUNTIFS('Work Items'!A:A,"Task",'Work Items'!D:D,B17,'Work Items'!L:L,"Completed"),"0")&" / "&TEXT(COUNTIFS('Work Items'!A:A,"Task",'Work Items'!D:D,B17),"0")&" Tasks" | P17: =TEXT(COUNTIFS('Work Items'!A:A,"Bug",'Work Items'!D:D,B17,'Work Items'!L:L,"Fixed"),"0")&" / "&TEXT(COUNTIFS('Work Items'!A:A,"Bug",'Work Items'!D:D,B17),"0")&" Bugs" | Q17: =TEXT(COUNTIFS('Work Items'!A:A,"Risk",'Work Items'!D:D,B17,'Work Items'!L:L,"Open"),"0")&" Open" | R17: =TEXT(COUNTIFS('Work Items'!A:A,"CR",'Work Items'!D:D,B17,'Work Items'!L:L,"Pending Approval"),"0")&" Pending" | S17: =IF(N17="TBD","Yellow",IF(ISNUMBER(N17),IF(N17<0,"Red",IF(N17<14,"Yellow","Green")),"Yellow")) | T17: =IF(NOT(ISNUMBER(M17)),"Yellow",IF(M17<0,"Red",IF(M17/I17<0.05,"Yellow","Green"))) | U17: =IF(OR(S17="Red",T17="Red"),"Red",IF(OR(S17="Yellow",T17="Yellow"),"Yellow","Green"))
... A155: =IFERROR(INDEX('Projects Master'!$A:$A,ROW()-1),"") | B155: =IFERROR(VLOOKUP(A155,'Projects Master'!$A:$I,2,0),"") | C155: =IFERROR(VLOOKUP(A155,'Projects Master'!$A:$I,3,0),"") | D155: =IFERROR(VLOOKUP(A155,'Projects Master'!$A:$I,4,0),"") | E155: =IFERROR(VLOOKUP(A155,'Projects Master'!$A:$I,5,0),"") | F155: =IFERROR(VLOOKUP(A155,'Projects Master'!$A:$I,6,0),"") | G155: =IFERROR(VLOOKUP(A155,'Projects Master'!$A:$I,7,0),"") | H155: =IFERROR(VLOOKUP(A155,'Projects Master'!$A:$I,8,0),"") | I155: =IFERROR(VLOOKUP(A155,'Projects Master'!$A:$I,9,0),"") | J155: =_xlfn.LET(_xlpm.t,_xlfn.MINIFS('Work Items'!P:P,'Work Items'!D:D,B155,'Work Items'!A:A,"Task"),_xlpm.b,_xlfn.MINIFS('Work Items'!P:P,'Work Items'!D:D,B155,'Work Items'!A:A,"Bug"),_xlpm.m,IF(AND(_xlpm.t=0,_xlpm.b=0),0,IF(_xlpm.t=0,_xlpm.b,IF(_xlpm.b=0,_xlpm.t,MIN(_xlpm.t,_xlpm.b)))),IF(_xlpm.m=0,G155,_xlpm.m)) | K155: =_xlfn.LET(_xlpm.t,_xlfn.MAXIFS('Work Items'!Q:Q,'Work Items'!D:D,B155,'Work Items'!A:A,"Task"),_xlpm.b,_xlfn.MAXIFS('Work Items'!Q:Q,'Work Items'!D:D,B155,'Work Items'!A:A,"Bug"),_xlpm.m,MAX(_xlpm.t,_xlpm.b),IF(_xlpm.m=0,H155,_xlpm.m)) | L155: =IFERROR(SUMIFS('Work Items'!O:O,'Work Items'!D:D,B155,'Work Items'!A:A,"Task"),0) | M155: =IF(ISNUMBER(I155),I155-L155,"N/A") | N155: =IF(AND(ISNUMBER(H155),K155>0),INT(H155-K155),"TBD") | O155: =TEXT(COUNTIFS('Work Items'!A:A,"Task",'Work Items'!D:D,B155,'Work Items'!L:L,"Completed"),"0")&" / "&TEXT(COUNTIFS('Work Items'!A:A,"Task",'Work Items'!D:D,B155),"0")&" Tasks" | P155: =TEXT(COUNTIFS('Work Items'!A:A,"Bug",'Work Items'!D:D,B155,'Work Items'!L:L,"Fixed"),"0")&" / "&TEXT(COUNTIFS('Work Items'!A:A,"Bug",'Work Items'!D:D,B155),"0")&" Bugs" | Q155: =TEXT(COUNTIFS('Work Items'!A:A,"Risk",'Work Items'!D:D,B155,'Work Items'!L:L,"Open"),"0")&" Open" | R155: =TEXT(COUNTIFS('Work Items'!A:A,"CR",'Work Items'!D:D,B155,'Work Items'!L:L,"Pending Approval"),"0")&" Pending" | S155: =IF(N155="TBD","Yellow",IF(ISNUMBER(N155),IF(N155<0,"Red",IF(N155<14,"Yellow","Green")),"Yellow")) | T155: =IF(NOT(ISNUMBER(M155)),"Yellow",IF(M155<0,"Red",IF(M155/I155<0.05,"Yellow","Green"))) | U155: =IF(OR(S155="Red",T155="Red"),"Red",IF(OR(S155="Yellow",T155="Yellow"),"Yellow","Green"))
A157: TOTALS | I157: =SUM(I6:I155) | L157: =SUM(L6:L155) | M157: =SUM(M6:M155)

Sheet Work Items
A1: OrbitFlow — Work Items (Tasks · Bugs · CRs · Risks)
A2: 🔍 Filter by Project: | B2: — All Projects — | F2: ← Select project to highlight rows | Use column filters (▼) to filter data
A3: Quick Stats ▶ | C3: Tasks | D3: =COUNTIFS(A6:A5000,"Task",D6:D5000,IF(B2="— All Projects —","*",B2)) | E3: Bugs | F3: =COUNTIFS(A6:A5000,"Bug",D6:D5000,IF(B2="— All Projects —","*",B2)) | G3: Risks | H3: =COUNTIFS(A6:A5000,"Risk",D6:D5000,IF(B2="— All Projects —","*",B2)) | I3: CRs | J3: =COUNTIFS(A6:A5000,"CR",D6:D5000,IF(B2="— All Projects —","*",B2)) | K3: Orig Hrs | L3: =SUMIFS(N6:N5000,D6:D5000,IF(B2="— All Projects —","*",B2)) | M3: Act Hrs | N3: =SUMIFS(O6:O5000,D6:D5000,IF(B2="— All Projects —","*",B2))
A5: Type | B5: ID | C5: Summary | D5: Module | E5: SubModule | F5: Event / BugType | G5: Category | H5: Activity | I5: Sub-Activity | J5: Assigned To | K5: Priority | L5: Status | M5: Worked Date | N5: Original Effort (hrs) | O5: Actual Effort (hrs) | P5: Start Date | Q5: End Date | R5: Probability (1-5) | S5: Impact (1-5) | T5: Mitigation Hrs | U5: Legacy Risk Score | V5: Description | W5: Story Points | X5: Remarks | Y5: Completed Date
A6: Task | B6: GCI-T001 | C6: Monthly Support - Case Management & Config | D6: GCI Phase 1 | E6: Case Management | F6: Configure | G6: Support | H6: Development | I6: Coding | J6: Prateek Shinde | K6: P2 | L6: Completed | M6: 46204 | N6: 80 | O6: 80 | P6: 46204 | Q6: 46218
A7: Task | B7: GCI-T002 | C7: Monthly Support - Field Service Optimization | D7: GCI Phase 1 | E7: Field Service | F7: Amend | G7: Support | H7: Development | I7: Coding | J7: Sudhakar Reddy Lekkala | K7: P2 | L7: Completed | M7: 46219 | N7: 80 | O7: 80 | P7: 46219 | Q7: 46234
A8: Task | B8: GCI-T003 | C8: Monthly Support - API Integration Review | D8: GCI Phase 1 | E8: API Integration | F8: Amend | G8: Support | H8: Development | I8: Coding | J8: Sudhakar Reddy Lekkala | K8: P2 | L8: In Progress | M8: 46235 | N8: 80 | O8: 60 | P8: 46235 | Q8: 46265
A9: Task | B9: GCI-T004 | C9: Canada Holiday Buffer - Aug Support Hours | D9: GCI Phase 1 | E9: Support Block | F9: Configure | G9: Support | H9: Development | I9: Coding | J9: Prateek Shinde | K9: P3 | L9: In Progress | M9: 46249 | N9: 40 | O9: 20 | P9: 46249 | Q9: 46265
A10: Bug | B10: GCI-B001 | C10: API timeout on bulk sync over 5000 records | D10: GCI Phase 1 | E10: API Integration | F10: Functional | G10: Bug Fix | H10: Resolution | I10: Code Fix | J10: Sudhakar Reddy Lekkala | K10: P2 | L10: Monitoring | M10: 46223 | N10: 8 | O10: 4 | P10: 46223 | Q10: 46265
A11: Risk | B11: GCI-RK001 | C11: Timezone Coordination Gap - Canada Team | D11: GCI Phase 1 | E11: Resource Management | F11: Resource Risk | G11: Risk Management | H11: Identification | I11: Risk Logging | J11: Gopikrishna Vemuri | K11: P2 | L11: Open | M11: 46204 | N11: 8 | O11: 2 | P11: 46204 | Q11: 46295 | T11: 8 | U11: 9
A12: Risk | B12: GCI-RK002 | C12: New Client Requirements Mid-Engagement | D12: GCI Phase 1 | E12: Scope Management | F12: Scope Risk | G12: Risk Management | H12: Identification | I12: Risk Logging | J12: Gopikrishna Vemuri | K12: P3 | L12: Open | M12: 46204 | N12: 4 | O12: 1 | P12: 46204 | Q12: 46387 | T12: 4 | U12: 8
A13: CR | B13: GCI-CR001 | C13: Canada Holiday Buffer Hours | D13: GCI Phase 1 | E13: Support Block | F13: Scope Addition | G13: Change Request | H13: Analysis | I13: Impact Analysis | J13: Gopikrishna Vemuri | K13: P3 | L13: Approved | M13: 46204 | N13: 40 | O13: 20 | P13: 46235 | Q13: 46265
A14: Task | B14: CTRL-T001 | C14: Requirements & BRD Review | D14: Control Solutions | E14: Sales Cloud | F14: Analyze | G14: Project Management | H14: Development | I14: Coding | J14: Ester Rani Ganji | K14: P1 | L14: Completed | M14: 46174 | N14: 12 | O14: 12 | P14: 46174 | Q14: 46176
A15: Task | B15: CTRL-T002 | C15: Salesforce Org Setup & Config | D15: Control Solutions | E15: Sales Cloud | F15: Configure | G15: Development | H15: Development | I15: Coding | J15: Jeevan Babu Paruchuri | K15: P1 | L15: Completed | M15: 46177 | N15: 20 | O15: 22 | P15: 46177 | Q15: 46183
A16: Task | B16: CTRL-T003 | C16: Data Model Design - Custom Objects | D16: Control Solutions | E16: Sales Cloud | F16: Create | G16: Development | H16: Development | I16: Coding | J16: Akhil Kotagiri | K16: P1 | L16: Completed | M16: 46177 | N16: 32 | O16: 35 | P16: 46177 | Q16: 46184
A17: Task | B17: CTRL-T004 | C17: Integration Architecture Blueprint | D17: Control Solutions | E17: QB Integration | F17: Analyze | G17: Development | H17: Development | I17: Coding | J17: Sureshkumar Gidugu | K17: P2 | L17: Completed | M17: 46180 | N17: 20 | O17: 18 | P17: 46180 | Q17: 46186
A18: Task | B18: CTRL-T005 | C18: Security & Permission Set Design | D18: Control Solutions | E18: Sales Cloud | F18: Configure | G18: Development | H18: Development | I18: Coding | J18: Nagarjuna Reddy Sadhu | K18: P2 | L18: Completed | M18: 46180 | N18: 12 | O18: 12 | P18: 46180 | Q18: 46183
A19: Task | B19: CTRL-T006 | C19: FSL Work Orders & Service Appointments | D19: Control Solutions | E19: FSL | F19: Create | G19: Development | H19: Development | I19: Coding | J19: Vishnudeep | K19: P1 | L19: Completed | M19: 46184 | N19: 32 | O19: 36 | P19: 46184 | Q19: 46193
A20: Task | B20: CTRL-T007 | C20: Service Cloud Case Management | D20: Control Solutions | E20: Service Cloud | F20: Create | G20: Development | H20: Development | I20: Coding | J20: Seeham Saber Hussain | K20: P1 | L20: Completed | M20: 46184 | N20: 20 | O20: 20 | P20: 46184 | Q20: 46190
A21: Task | B21: CTRL-T008 | C21: QB Integration - Design Phase | D21: Control Solutions | E21: QB Integration | F21: Create | G21: Development | H21: Development | I21: Coding | J21: Sureshkumar Gidugu | K21: P1 | L21: In Progress | M21: 46191 | N21: 32 | O21: 20 | P21: 46191 | Q21: 46214
A22: Task | B22: CTRL-T009 | C22: UAT Test Plan Creation | D22: Control Solutions | E22: UAT | F22: Create | G22: QA - Testing | H22: Development | I22: Coding | J22: Tejaswini Reddy Tamma | K22: P2 | L22: Completed | M22: 46188 | N22: 12 | O22: 12 | P22: 46188 | Q22: 46191
A23: Task | B23: CTRL-T010 | C23: Custom Report Development - 40 hrs | D23: Control Solutions | E23: Reports | F23: Create | G23: Development | H23: Development | I23: Coding | J23: Nagarjuna Reddy Sadhu | K23: P3 | L23: Completed | M23: 46193 | N23: 40 | O23: 42 | P23: 46193 | Q23: 46203
A24: Task | B24: CTRL-T011 | C24: UAT Execution & Client Sign-off | D24: Control Solutions | E24: UAT | F24: Test | G24: QA - Testing | H24: Development | I24: Coding | J24: Tejaswini Reddy Tamma | K24: P1 | L24: In Progress | M24: 46203 | N24: 20 | O24: 10 | P24: 46203 | Q24: 46214
... A26: Task | B26: CTRL-T013 | C26: Bug Fixes Round 1 | D26: Control Solutions | E26: Sales Cloud | F26: Amend | G26: Development | H26: Development | I26: Coding | J26: Jeevan Babu Paruchuri | K26: P1 | L26: In Progress | M26: 46203 | N26: 20 | O26: 8 | P26: 46203 | Q26: 46214
A27: Task | B27: CTRL-T014 | C27: Go-Live Preparation & Checklist | D27: Control Solutions | E27: Deployment | F27: Create | G27: Project Management | H27: Development | I27: Coding | J27: Ester Rani Ganji | K27: P1 | L27: To Do | N27: 12 | O27: 0 | P27: 46215 | Q27: 46221
A28: Task | B28: CTRL-T015 | C28: Production Deployment | D28: Control Solutions | E28: Deployment | F28: Deploy | G28: Development | H28: Development | I28: Coding | J28: Akhil Kotagiri | K28: P1 | L28: To Do | N28: 12 | O28: 0 | P28: 46221 | Q28: 46224
A29: Bug | B29: CTRL-B001 | C29: FSL Work Order not auto-creating Service Appointment | D29: Control Solutions | E29: FSL | F29: Functional | G29: Bug Fix | H29: Resolution | I29: Code Fix | J29: Vishnudeep | K29: P1 | L29: Fixed | M29: 46191 | N29: 6 | O29: 4 | P29: 46191 | Q29: 46194
A30: Bug | B30: CTRL-B002 | C30: QB sync creating duplicate invoice records | D30: Control Solutions | E30: QB Integration | F30: Integration Bug | G30: Bug Fix | H30: Resolution | I30: Code Fix | J30: Sureshkumar Gidugu | K30: P1 | L30: In Progress | M30: 46195 | N30: 8 | O30: 4 | P30: 46195 | Q30: 46214
A31: Bug | B31: CTRL-B003 | C31: Custom report date filter ignoring timezone offset | D31: Control Solutions | E31: Reports | F31: Functional | G31: Bug Fix | H31: Resolution | I31: Code Fix | J31: Nagarjuna Reddy Sadhu | K31: P3 | L31: Open | M31: 46201 | N31: 4 | O31: 0 | P31: 46201 | Q31: 46214
A32: Bug | B32: CTRL-B004 | C32: Permission set missing field access for Service Manager | D32: Control Solutions | E32: Sales Cloud | F32: Config Bug | G32: Bug Fix | H32: Resolution | I32: Code Fix | J32: Akhil Kotagiri | K32: P2 | L32: Fixed | M32: 46202 | N32: 4 | O32: 3 | P32: 46202 | Q32: 46203
A33: Risk | B33: CTRL-RK001 | C33: Effort Overrun - 107 Hours | D33: Control Solutions | E33: Financial Management | F33: Financial Risk | G33: Risk Management | H33: Identification | I33: Risk Logging | J33: Ester Rani Ganji | K33: P1 | L33: Open | M33: 46203 | N33: 16 | O33: 8 | P33: 46203 | Q33: 46229 | T33: 16 | U33: 25
A34: Risk | B34: CTRL-RK002 | C34: QB Integration - Unscoped Requirement | D34: Control Solutions | E34: QB Integration | F34: Technical Risk | G34: Risk Management | H34: Identification | I34: Risk Logging | J34: Ester Rani Ganji | K34: P1 | L34: Open | M34: 46193 | N34: 8 | O34: 4 | P34: 46193 | Q34: 46244 | T34: 8 | U34: 16
A35: CR | B35: CTRL-CR001 | C35: QB Integration - New Scope Addition | D35: Control Solutions | E35: QB Integration | F35: Scope Addition | G35: Change Request | H35: Analysis | I35: Impact Analysis | J35: Ester Rani Ganji | K35: P1 | L35: Pending Approval | M35: 46193 | N35: 150 | O35: 0 | P35: 46193 | Q35: 46229
A36: CR | B36: CTRL-CR002 | C36: Additional Custom Reports - 40 hrs | D36: Control Solutions | E36: Reports | F36: Enhancement | G36: Change Request | H36: Analysis | I36: Impact Analysis | J36: Ester Rani Ganji | K36: P2 | L36: Approved | M36: 46184 | N36: 40 | O36: 42 | P36: 46184 | Q36: 46203
A37: Task | B37: LEV-T001 | C37: Levata Support - Jul Tasks | D37: Levata | E37: Sales Cloud | F37: Configure | G37: Support | H37: Development | I37: Coding | J37: Kailash Reddy | K37: P2 | L37: Completed | M37: 46204 | N37: 160 | O37: 160 | P37: 46204 | Q37: 46234
A38: Task | B38: LEV-T002 | C38: Levata Support - Aug Tasks | D38: Levata | E38: Sales Cloud | F38: Amend | G38: Support | H38: Development | I38: Coding | J38: Mohandasaiah Garikapati | K38: P2 | L38: In Progress | M38: 46235 | N38: 160 | O38: 80 | P38: 46235 | Q38: 46265
A39: Task | B39: LEV-T003 | C39: SOW Amendment Coordination | D39: Levata | E39: Scope Management | F39: Analyze | G39: Project Management | H39: Development | I39: Coding | J39: Ester Rani Ganji | K39: P2 | L39: In Progress | M39: 46218 | N39: 16 | O39: 8 | P39: 46218 | Q39: 46249
A40: Bug | B40: LEV-B001 | C40: Dashboard filters not persisting across sessions | D40: Levata | E40: Reports | F40: Functional | G40: Bug Fix | H40: Resolution | I40: Code Fix | J40: Kailash Reddy | K40: P3 | L40: Open | M40: 46235 | N40: 4 | O40: 0 | P40: 46235 | Q40: 46249
A41: Risk | B41: LEV-RK001 | C41: AR Outstanding $13,160 | D41: Levata | E41: Financial Management | F41: Financial Risk | G41: Risk Management | H41: Identification | I41: Risk Logging | J41: Ester Rani Ganji | K41: P2 | L41: Monitoring | M41: 46204 | N41: 8 | O41: 4 | P41: 46204 | Q41: 46265 | T41: 8 | U41: 25
A42: Risk | B42: LEV-RK002 | C42: SOW Revenue Overrun | D42: Levata | E42: Scope Management | F42: Scope Risk | G42: Risk Management | H42: Identification | I42: Risk Logging | J42: Ester Rani Ganji | K42: P2 | L42: Open | M42: 46204 | N42: 8 | O42: 2 | P42: 46204 | Q42: 46249 | T42: 8 | U42: 8
...

Sheet Resources
A1: OrbitFlow — Resource Utilization | Formulas from Work Items
A2: Sprint Cap = 136 hrs · A ≥ 90% · B 50–89% · C < 50% · Overloaded > 100%
A5: RESOURCE MASTER (Org Roster)
A6: Employee | B6: Level | C6: Manager | D6: Role | E6: Resource Type | F6: Task Hrs (from Tasks) | G6: Bug Hrs (Testing/UAT/PS) | H6: Total Hrs | I6: Util % | J6: Working Cap (hrs) | K6: Onsite/Offshore | L6: JULY 2026 CAPACITY | N6: Email | O6: Designation | P6: Availability % | Q6: Billing Rate ($/hr) | R6: Joining Date | S6: Skills | T6: Experience (yrs)
A7: Gopikrishna Vemuri | B7: 1 | C7: - | D7: COO | E7: Executive | F7: =SUMIFS('Work Items'!$O:$O,'Work Items'!$A:$A,"Task",'Work Items'!$J:$J,$A7,'Work Items'!$M:$M,">="&$M$7,'Work Items'!$M:$M,"<="&$M$8) | G7: =SUMIFS('Work Items'!$O:$O,'Work Items'!$A:$A,"Bug",'Work Items'!$J:$J,$A7,'Work Items'!$M:$M,">="&$M$7,'Work Items'!$M:$M,"<="&$M$8) | H7: =F7+G7 | I7: =IF($J7=0,0,$H7/$J7) | J7: =$M$11 | K7: Onsite | L7: Period Start | M7: 46204 | P7: 100
A8: Gopinath Vedantham | B8: 2 | C8: Gopikrishna Vemuri | D8: Project Lead | E8: MGMT | F8: =SUMIFS('Work Items'!$O:$O,'Work Items'!$A:$A,"Task",'Work Items'!$J:$J,$A8,'Work Items'!$M:$M,">="&$M$7,'Work Items'!$M:$M,"<="&$M$8) | G8: =SUMIFS('Work Items'!$O:$O,'Work Items'!$A:$A,"Bug",'Work Items'!$J:$J,$A8,'Work Items'!$M:$M,">="&$M$7,'Work Items'!$M:$M,"<="&$M$8) | H8: =F8+G8 | I8: =IF($J8=0,0,$H8/$J8) | J8: =$M$11 | K8: Onsite | L8: Period End | M8: 46234 | P8: 100
A9: Deepti Bhatt | B9: 3 | C9: Gopinath Vedantham | D9: Solution Lead | E9: Solution-Lead | F9: =SUMIFS('Work Items'!$O:$O,'Work Items'!$A:$A,"Task",'Work Items'!$J:$J,$A9,'Work Items'!$M:$M,">="&$M$7,'Work Items'!$M:$M,"<="&$M$8) | G9: =SUMIFS('Work Items'!$O:$O,'Work Items'!$A:$A,"Bug",'Work Items'!$J:$J,$A9,'Work Items'!$M:$M,">="&$M$7,'Work Items'!$M:$M,"<="&$M$8) | H9: =F9+G9 | I9: =IF($J9=0,0,$H9/$J9) | J9: =$M$11 | K9: Offshore | L9: Hrs / Day | M9: 8 | P9: 100
A10: Murali Meruva | B10: 3 | C10: Gopinath Vedantham | D10: Solution Lead | E10: Solution-Lead | F10: =SUMIFS('Work Items'!$O:$O,'Work Items'!$A:$A,"Task",'Work Items'!$J:$J,$A10,'Work Items'!$M:$M,">="&$M$7,'Work Items'!$M:$M,"<="&$M$8) | G10: =SUMIFS('Work Items'!$O:$O,'Work Items'!$A:$A,"Bug",'Work Items'!$J:$J,$A10,'Work Items'!$M:$M,">="&$M$7,'Work Items'!$M:$M,"<="&$M$8) | H10: =F10+G10 | I10: =IF($J10=0,0,$H10/$J10) | J10: =$M$11 | K10: Offshore | L10: Working Days | M10: =NETWORKDAYS(M7,M8) | P10: 100
A11: Amar Joshi | B11: 3 | C11: Gopinath Vedantham | D11: UI Lead | E11: UI-Lead | F11: =SUMIFS('Work Items'!$O:$O,'Work Items'!$A:$A,"Task",'Work Items'!$J:$J,$A11,'Work Items'!$M:$M,">="&$M$7,'Work Items'!$M:$M,"<="&$M$8) | G11: =SUMIFS('Work Items'!$O:$O,'Work Items'!$A:$A,"Bug",'Work Items'!$J:$J,$A11,'Work Items'!$M:$M,">="&$M$7,'Work Items'!$M:$M,"<="&$M$8) | H11: =F11+G11 | I11: =IF($J11=0,0,$H11/$J11) | J11: =$M$11 | K11: Offshore | L11: Full Cap (hrs) | M11: =M10*M9 | P11: 100
A12: Jogesh Somisetti | B12: 3 | C12: Gopinath Vedantham | D12: Backend Lead | E12: Backend | F12: =SUMIFS('Work Items'!$O:$O,'Work Items'!$A:$A,"Task",'Work Items'!$J:$J,$A12,'Work Items'!$M:$M,">="&$M$7,'Work Items'!$M:$M,"<="&$M$8) | G12: =SUMIFS('Work Items'!$O:$O,'Work Items'!$A:$A,"Bug",'Work Items'!$J:$J,$A12,'Work Items'!$M:$M,">="&$M$7,'Work Items'!$M:$M,"<="&$M$8) | H12: =F12+G12 | I12: =IF($J12=0,0,$H12/$J12) | J12: =$M$11 | K12: Offshore | P12: 100
A13: Lakshit Sharma | B13: 3 | C13: Gopinath Vedantham | D13: Backend Lead | E13: Backend | F13: =SUMIFS('Work Items'!$O:$O,'Work Items'!$A:$A,"Task",'Work Items'!$J:$J,$A13,'Work Items'!$M:$M,">="&$M$7,'Work Items'!$M:$M,"<="&$M$8) | G13: =SUMIFS('Work Items'!$O:$O,'Work Items'!$A:$A,"Bug",'Work Items'!$J:$J,$A13,'Work Items'!$M:$M,">="&$M$7,'Work Items'!$M:$M,"<="&$M$8) | H13: =F13+G13 | I13: =IF($J13=0,0,$H13/$J13) | J13: =$M$11 | K13: Offshore | P13: 100
A14: Kishore Kumar G | B14: 3 | C14: Gopinath Vedantham | D14: Backend Lead | E14: Backend | F14: =SUMIFS('Work Items'!$O:$O,'Work Items'!$A:$A,"Task",'Work Items'!$J:$J,$A14,'Work Items'!$M:$M,">="&$M$7,'Work Items'!$M:$M,"<="&$M$8) | G14: =SUMIFS('Work Items'!$O:$O,'Work Items'!$A:$A,"Bug",'Work Items'!$J:$J,$A14,'Work Items'!$M:$M,">="&$M$7,'Work Items'!$M:$M,"<="&$M$8) | H14: =F14+G14 | I14: =IF($J14=0,0,$H14/$J14) | J14: =$M$11 | K14: Offshore | P14: 100
A15: Praveen Murugesan | B15: 3 | C15: Gopinath Vedantham | D15: QA Lead | E15: QA-Lead | F15: =SUMIFS('Work Items'!$O:$O,'Work Items'!$A:$A,"Task",'Work Items'!$J:$J,$A15,'Work Items'!$M:$M,">="&$M$7,'Work Items'!$M:$M,"<="&$M$8) | G15: =SUMIFS('Work Items'!$O:$O,'Work Items'!$A:$A,"Bug",'Work Items'!$J:$J,$A15,'Work Items'!$M:$M,">="&$M$7,'Work Items'!$M:$M,"<="&$M$8) | H15: =F15+G15 | I15: =IF($J15=0,0,$H15/$J15) | J15: =$M$11 | K15: Offshore | P15: 100
A16: Likhitha Vaddevalli | B16: 4 | C16: Deepti Bhatt | D16: Solution Analyst | E16: Solution | F16: =SUMIFS('Work Items'!$O:$O,'Work Items'!$A:$A,"Task",'Work Items'!$J:$J,$A16,'Work Items'!$M:$M,">="&$M$7,'Work Items'!$M:$M,"<="&$M$8) | G16: =SUMIFS('Work Items'!$O:$O,'Work Items'!$A:$A,"Bug",'Work Items'!$J:$J,$A16,'Work Items'!$M:$M,">="&$M$7,'Work Items'!$M:$M,"<="&$M$8) | H16: =F16+G16 | I16: =IF($J16=0,0,$H16/$J16) | J16: =$M$11 | K16: Offshore | P16: 100
A17: Lakshmi Vaggala | B17: 4 | C17: Amar Joshi | D17: UI Developer | E17: UI | F17: =SUMIFS('Work Items'!$O:$O,'Work Items'!$A:$A,"Task",'Work Items'!$J:$J,$A17,'Work Items'!$M:$M,">="&$M$7,'Work Items'!$M:$M,"<="&$M$8) | G17: =SUMIFS('Work Items'!$O:$O,'Work Items'!$A:$A,"Bug",'Work Items'!$J:$J,$A17,'Work Items'!$M:$M,">="&$M$7,'Work Items'!$M:$M,"<="&$M$8) | H17: =F17+G17 | I17: =IF($J17=0,0,$H17/$J17) | J17: =$M$11 | K17: Offshore | P17: 100
A18: Sravani Palle | B18: 4 | C18: Amar Joshi | D18: UI Developer | E18: UI | F18: =SUMIFS('Work Items'!$O:$O,'Work Items'!$A:$A,"Task",'Work Items'!$J:$J,$A18,'Work Items'!$M:$M,">="&$M$7,'Work Items'!$M:$M,"<="&$M$8) | G18: =SUMIFS('Work Items'!$O:$O,'Work Items'!$A:$A,"Bug",'Work Items'!$J:$J,$A18,'Work Items'!$M:$M,">="&$M$7,'Work Items'!$M:$M,"<="&$M$8) | H18: =F18+G18 | I18: =IF($J18=0,0,$H18/$J18) | J18: =$M$11 | K18: Offshore | P18: 100
A19: Kamala Rudru | B19: 4 | C19: Amar Joshi | D19: UI Developer | E19: UI | F19: =SUMIFS('Work Items'!$O:$O,'Work Items'!$A:$A,"Task",'Work Items'!$J:$J,$A19,'Work Items'!$M:$M,">="&$M$7,'Work Items'!$M:$M,"<="&$M$8) | G19: =SUMIFS('Work Items'!$O:$O,'Work Items'!$A:$A,"Bug",'Work Items'!$J:$J,$A19,'Work Items'!$M:$M,">="&$M$7,'Work Items'!$M:$M,"<="&$M$8) | H19: =F19+G19 | I19: =IF($J19=0,0,$H19/$J19) | J19: =$M$11 | K19: Offshore | P19: 100
A20: Mahendra Bhalsing | B20: 4 | C20: Jogesh Somisetti | D20: Backend Developer | E20: Backend | F20: =SUMIFS('Work Items'!$O:$O,'Work Items'!$A:$A,"Task",'Work Items'!$J:$J,$A20,'Work Items'!$M:$M,">="&$M$7,'Work Items'!$M:$M,"<="&$M$8) | G20: =SUMIFS('Work Items'!$O:$O,'Work Items'!$A:$A,"Bug",'Work Items'!$J:$J,$A20,'Work Items'!$M:$M,">="&$M$7,'Work Items'!$M:$M,"<="&$M$8) | H20: =F20+G20 | I20: =IF($J20=0,0,$H20/$J20) | J20: =$M$11 | K20: Offshore | P20: 100
A21: Kapil Meshram | B21: 4 | C21: Jogesh Somisetti | D21: Backend Developer | E21: Backend | F21: =SUMIFS('Work Items'!$O:$O,'Work Items'!$A:$A,"Task",'Work Items'!$J:$J,$A21,'Work Items'!$M:$M,">="&$M$7,'Work Items'!$M:$M,"<="&$M$8) | G21: =SUMIFS('Work Items'!$O:$O,'Work Items'!$A:$A,"Bug",'Work Items'!$J:$J,$A21,'Work Items'!$M:$M,">="&$M$7,'Work Items'!$M:$M,"<="&$M$8) | H21: =F21+G21 | I21: =IF($J21=0,0,$H21/$J21) | J21: =$M$11 | K21: Offshore | P21: 100
A22: Rajeshwar Thakur | B22: 4 | C22: Jogesh Somisetti | D22: Backend Developer | E22: Backend | F22: =SUMIFS('Work Items'!$O:$O,'Work Items'!$A:$A,"Task",'Work Items'!$J:$J,$A22,'Work Items'!$M:$M,">="&$M$7,'Work Items'!$M:$M,"<="&$M$8) | G22: =SUMIFS('Work Items'!$O:$O,'Work Items'!$A:$A,"Bug",'Work Items'!$J:$J,$A22,'Work Items'!$M:$M,">="&$M$7,'Work Items'!$M:$M,"<="&$M$8) | H22: =F22+G22 | I22: =IF($J22=0,0,$H22/$J22) | J22: =$M$11 | K22: Offshore | P22: 100
A23: Lokesh Kundlavari | B23: 4 | C23: Lakshit Sharma | D23: Backend Developer | E23: Backend | F23: =SUMIFS('Work Items'!$O:$O,'Work Items'!$A:$A,"Task",'Work Items'!$J:$J,$A23,'Work Items'!$M:$M,">="&$M$7,'Work Items'!$M:$M,"<="&$M$8) | G23: =SUMIFS('Work Items'!$O:$O,'Work Items'!$A:$A,"Bug",'Work Items'!$J:$J,$A23,'Work Items'!$M:$M,">="&$M$7,'Work Items'!$M:$M,"<="&$M$8) | H23: =F23+G23 | I23: =IF($J23=0,0,$H23/$J23) | J23: =$M$11 | K23: Offshore | P23: 100
... A38: Swati Vivek | B38: 4 | C38: Gopinath Vedantham | D38: Infra Engineer | E38: Infra | F38: =SUMIFS('Work Items'!$O:$O,'Work Items'!$A:$A,"Task",'Work Items'!$J:$J,$A38,'Work Items'!$M:$M,">="&$M$7,'Work Items'!$M:$M,"<="&$M$8) | G38: =SUMIFS('Work Items'!$O:$O,'Work Items'!$A:$A,"Bug",'Work Items'!$J:$J,$A38,'Work Items'!$M:$M,">="&$M$7,'Work Items'!$M:$M,"<="&$M$8) | H38: =F38+G38 | I38: =IF($J38=0,0,$H38/$J38) | J38: =$M$11 | K38: Offshore | P38: 100
A39: Kishore Meka | B39: 4 | C39: Murali Meruva | D39: Project Manager | E39: PM | F39: =SUMIFS('Work Items'!$O:$O,'Work Items'!$A:$A,"Task",'Work Items'!$J:$J,$A39,'Work Items'!$M:$M,">="&$M$7,'Work Items'!$M:$M,"<="&$M$8) | G39: =SUMIFS('Work Items'!$O:$O,'Work Items'!$A:$A,"Bug",'Work Items'!$J:$J,$A39,'Work Items'!$M:$M,">="&$M$7,'Work Items'!$M:$M,"<="&$M$8) | H39: =F39+G39 | I39: =IF($J39=0,0,$H39/$J39) | J39: 80 | K39: Offshore | P39: 100
A40: Waliu Faleye | B40: 5 | C40: Kishore Meka | D40: Backend Developer | E40: Backend | F40: =SUMIFS('Work Items'!$O:$O,'Work Items'!$A:$A,"Task",'Work Items'!$J:$J,$A40,'Work Items'!$M:$M,">="&$M$7,'Work Items'!$M:$M,"<="&$M$8) | G40: =SUMIFS('Work Items'!$O:$O,'Work Items'!$A:$A,"Bug",'Work Items'!$J:$J,$A40,'Work Items'!$M:$M,">="&$M$7,'Work Items'!$M:$M,"<="&$M$8) | H40: =F40+G40 | I40: =IF($J40=0,0,$H40/$J40) | J40: 0 | K40: Offshore | P40: 100
A41: Raudha Ahmed | B41: 5 | C41: Kishore Meka | D41: Backend Developer | E41: Backend | F41: =SUMIFS('Work Items'!$O:$O,'Work Items'!$A:$A,"Task",'Work Items'!$J:$J,$A41,'Work Items'!$M:$M,">="&$M$7,'Work Items'!$M:$M,"<="&$M$8) | G41: =SUMIFS('Work Items'!$O:$O,'Work Items'!$A:$A,"Bug",'Work Items'!$J:$J,$A41,'Work Items'!$M:$M,">="&$M$7,'Work Items'!$M:$M,"<="&$M$8) | H41: =F41+G41 | I41: =IF($J41=0,0,$H41/$J41) | J41: 0 | K41: Offshore | P41: 100
A42: Sreenu Bhupati | B42: 5 | C42: Kishore Meka | D42: Backend Developer | E42: Backend | F42: =SUMIFS('Work Items'!$O:$O,'Work Items'!$A:$A,"Task",'Work Items'!$J:$J,$A42,'Work Items'!$M:$M,">="&$M$7,'Work Items'!$M:$M,"<="&$M$8) | G42: =SUMIFS('Work Items'!$O:$O,'Work Items'!$A:$A,"Bug",'Work Items'!$J:$J,$A42,'Work Items'!$M:$M,">="&$M$7,'Work Items'!$M:$M,"<="&$M$8) | H42: =F42+G42 | I42: =IF($J42=0,0,$H42/$J42) | J42: 0 | K42: Offshore | P42: 100
A43: Praveen Venkatesh | B43: 5 | C43: Kishore Meka | D43: QA Analyst | E43: QA | F43: =SUMIFS('Work Items'!$O:$O,'Work Items'!$A:$A,"Task",'Work Items'!$J:$J,$A43,'Work Items'!$M:$M,">="&$M$7,'Work Items'!$M:$M,"<="&$M$8) | G43: =SUMIFS('Work Items'!$O:$O,'Work Items'!$A:$A,"Bug",'Work Items'!$J:$J,$A43,'Work Items'!$M:$M,">="&$M$7,'Work Items'!$M:$M,"<="&$M$8) | H43: =F43+G43 | I43: =IF($J43=0,0,$H43/$J43) | J43: 80 | K43: Offshore | P43: 100
A44: Sriram Vanumu | B44: 4 | C44: Jogesh Somisetti | D44: Backend Developer | E44: Backend | F44: =SUMIFS('Work Items'!$O:$O,'Work Items'!$A:$A,"Task",'Work Items'!$J:$J,$A44,'Work Items'!$M:$M,">="&$M$7,'Work Items'!$M:$M,"<="&$M$8) | G44: =SUMIFS('Work Items'!$O:$O,'Work Items'!$A:$A,"Bug",'Work Items'!$J:$J,$A44,'Work Items'!$M:$M,">="&$M$7,'Work Items'!$M:$M,"<="&$M$8) | H44: =F44+G44 | I44: =IF($J44=0,0,$H44/$J44) | J44: =$M$11 | K44: Offshore | P44: 100
A45: Rajkumar Pichhiguntla | B45: 4 | C45: Lakshit Sharma | D45: Backend Developer | E45: Backend | F45: =SUMIFS('Work Items'!$O:$O,'Work Items'!$A:$A,"Task",'Work Items'!$J:$J,$A45,'Work Items'!$M:$M,">="&$M$7,'Work Items'!$M:$M,"<="&$M$8) | G45: =SUMIFS('Work Items'!$O:$O,'Work Items'!$A:$A,"Bug",'Work Items'!$J:$J,$A45,'Work Items'!$M:$M,">="&$M$7,'Work Items'!$M:$M,"<="&$M$8) | H45: =F45+G45 | I45: =IF($J45=0,0,$H45/$J45) | J45: =$M$11 | K45: Offshore | P45: 100
A46: Janakiram Ankam | B46: 4 | C46: Kishore Kumar G | D46: Integration Developer | E46: Integration | F46: =SUMIFS('Work Items'!$O:$O,'Work Items'!$A:$A,"Task",'Work Items'!$J:$J,$A46,'Work Items'!$M:$M,">="&$M$7,'Work Items'!$M:$M,"<="&$M$8) | G46: =SUMIFS('Work Items'!$O:$O,'Work Items'!$A:$A,"Bug",'Work Items'!$J:$J,$A46,'Work Items'!$M:$M,">="&$M$7,'Work Items'!$M:$M,"<="&$M$8) | H46: =F46+G46 | I46: =IF($J46=0,0,$H46/$J46) | J46: =$M$11 | K46: Offshore | P46: 100
A48: Note: Orange rows = Support Team (80 hrs capacity vs 136).

Sheet Planned vs Actual
A1: OrbitFlow — Planned vs Actual Effort | Formulas from Work Items
A2: Planned = Original Effort (hrs) · Actual = Actual Effort (hrs) · Variance = Planned − Actual · Source: Work Items sheet
A4: Resource | B4: Module (Project) | C4: Type | D4: Planned Hrs | E4: Actual Hrs | F4: Variance | G4: Variance % | H4: Status
A5: Chaitanya Goriparthi | B5: 4Media Phase 3 | C5: Bug | D5: =IFERROR(SUMIFS('Work Items'!N:N,'Work Items'!J:J,A5,'Work Items'!D:D,B5,'Work Items'!A:A,C5),0) | E5: =IFERROR(SUMIFS('Work Items'!O:O,'Work Items'!J:J,A5,'Work Items'!D:D,B5,'Work Items'!A:A,C5),0) | F5: =D5-E5 | G5: =IFERROR((D5-E5)/D5,0) | H5: =IF(F5>0,"Ahead "& TEXT(ABS(F5),"0")&" hrs",IF(F5<0,"Behind "& TEXT(ABS(F5),"0")&" hrs","On Track"))
A6: Chaitanya Goriparthi | B6: 4Media Phase 3 | C6: Task | D6: =IFERROR(SUMIFS('Work Items'!N:N,'Work Items'!J:J,A6,'Work Items'!D:D,B6,'Work Items'!A:A,C6),0) | E6: =IFERROR(SUMIFS('Work Items'!O:O,'Work Items'!J:J,A6,'Work Items'!D:D,B6,'Work Items'!A:A,C6),0) | F6: =D6-E6 | G6: =IFERROR((D6-E6)/D6,0) | H6: =IF(F6>0,"Ahead "& TEXT(ABS(F6),"0")&" hrs",IF(F6<0,"Behind "& TEXT(ABS(F6),"0")&" hrs","On Track"))
A7: Dee Reddy | B7: 4Media Phase 3 | C7: Task | D7: =IFERROR(SUMIFS('Work Items'!N:N,'Work Items'!J:J,A7,'Work Items'!D:D,B7,'Work Items'!A:A,C7),0) | E7: =IFERROR(SUMIFS('Work Items'!O:O,'Work Items'!J:J,A7,'Work Items'!D:D,B7,'Work Items'!A:A,C7),0) | F7: =D7-E7 | G7: =IFERROR((D7-E7)/D7,0) | H7: =IF(F7>0,"Ahead "& TEXT(ABS(F7),"0")&" hrs",IF(F7<0,"Behind "& TEXT(ABS(F7),"0")&" hrs","On Track"))
A8: Dhikshitha Rekulapally | B8: 4Media Phase 3 | C8: Task | D8: =IFERROR(SUMIFS('Work Items'!N:N,'Work Items'!J:J,A8,'Work Items'!D:D,B8,'Work Items'!A:A,C8),0) | E8: =IFERROR(SUMIFS('Work Items'!O:O,'Work Items'!J:J,A8,'Work Items'!D:D,B8,'Work Items'!A:A,C8),0) | F8: =D8-E8 | G8: =IFERROR((D8-E8)/D8,0) | H8: =IF(F8>0,"Ahead "& TEXT(ABS(F8),"0")&" hrs",IF(F8<0,"Behind "& TEXT(ABS(F8),"0")&" hrs","On Track"))
A9: Vasudev Irla | B9: 4Media Phase 3 | C9: Bug | D9: =IFERROR(SUMIFS('Work Items'!N:N,'Work Items'!J:J,A9,'Work Items'!D:D,B9,'Work Items'!A:A,C9),0) | E9: =IFERROR(SUMIFS('Work Items'!O:O,'Work Items'!J:J,A9,'Work Items'!D:D,B9,'Work Items'!A:A,C9),0) | F9: =D9-E9 | G9: =IFERROR((D9-E9)/D9,0) | H9: =IF(F9>0,"Ahead "& TEXT(ABS(F9),"0")&" hrs",IF(F9<0,"Behind "& TEXT(ABS(F9),"0")&" hrs","On Track"))
A10: Vasudev Irla | B10: 4Media Phase 3 | C10: Task | D10: =IFERROR(SUMIFS('Work Items'!N:N,'Work Items'!J:J,A10,'Work Items'!D:D,B10,'Work Items'!A:A,C10),0) | E10: =IFERROR(SUMIFS('Work Items'!O:O,'Work Items'!J:J,A10,'Work Items'!D:D,B10,'Work Items'!A:A,C10),0) | F10: =D10-E10 | G10: =IFERROR((D10-E10)/D10,0) | H10: =IF(F10>0,"Ahead "& TEXT(ABS(F10),"0")&" hrs",IF(F10<0,"Behind "& TEXT(ABS(F10),"0")&" hrs","On Track"))
A11: Akhil Kotagiri | B11: Control Solutions | C11: Bug | D11: =IFERROR(SUMIFS('Work Items'!N:N,'Work Items'!J:J,A11,'Work Items'!D:D,B11,'Work Items'!A:A,C11),0) | E11: =IFERROR(SUMIFS('Work Items'!O:O,'Work Items'!J:J,A11,'Work Items'!D:D,B11,'Work Items'!A:A,C11),0) | F11: =D11-E11 | G11: =IFERROR((D11-E11)/D11,0) | H11: =IF(F11>0,"Ahead "& TEXT(ABS(F11),"0")&" hrs",IF(F11<0,"Behind "& TEXT(ABS(F11),"0")&" hrs","On Track"))
A12: Akhil Kotagiri | B12: Control Solutions | C12: Task | D12: =IFERROR(SUMIFS('Work Items'!N:N,'Work Items'!J:J,A12,'Work Items'!D:D,B12,'Work Items'!A:A,C12),0) | E12: =IFERROR(SUMIFS('Work Items'!O:O,'Work Items'!J:J,A12,'Work Items'!D:D,B12,'Work Items'!A:A,C12),0) | F12: =D12-E12 | G12: =IFERROR((D12-E12)/D12,0) | H12: =IF(F12>0,"Ahead "& TEXT(ABS(F12),"0")&" hrs",IF(F12<0,"Behind "& TEXT(ABS(F12),"0")&" hrs","On Track"))
A13: Ester Rani Ganji | B13: Control Solutions | C13: Task | D13: =IFERROR(SUMIFS('Work Items'!N:N,'Work Items'!J:J,A13,'Work Items'!D:D,B13,'Work Items'!A:A,C13),0) | E13: =IFERROR(SUMIFS('Work Items'!O:O,'Work Items'!J:J,A13,'Work Items'!D:D,B13,'Work Items'!A:A,C13),0) | F13: =D13-E13 | G13: =IFERROR((D13-E13)/D13,0) | H13: =IF(F13>0,"Ahead "& TEXT(ABS(F13),"0")&" hrs",IF(F13<0,"Behind "& TEXT(ABS(F13),"0")&" hrs","On Track"))
A14: Jeevan Babu Paruchuri | B14: Control Solutions | C14: Task | D14: =IFERROR(SUMIFS('Work Items'!N:N,'Work Items'!J:J,A14,'Work Items'!D:D,B14,'Work Items'!A:A,C14),0) | E14: =IFERROR(SUMIFS('Work Items'!O:O,'Work Items'!J:J,A14,'Work Items'!D:D,B14,'Work Items'!A:A,C14),0) | F14: =D14-E14 | G14: =IFERROR((D14-E14)/D14,0) | H14: =IF(F14>0,"Ahead "& TEXT(ABS(F14),"0")&" hrs",IF(F14<0,"Behind "& TEXT(ABS(F14),"0")&" hrs","On Track"))
A15: Nagarjuna Reddy Sadhu | B15: Control Solutions | C15: Bug | D15: =IFERROR(SUMIFS('Work Items'!N:N,'Work Items'!J:J,A15,'Work Items'!D:D,B15,'Work Items'!A:A,C15),0) | E15: =IFERROR(SUMIFS('Work Items'!O:O,'Work Items'!J:J,A15,'Work Items'!D:D,B15,'Work Items'!A:A,C15),0) | F15: =D15-E15 | G15: =IFERROR((D15-E15)/D15,0) | H15: =IF(F15>0,"Ahead "& TEXT(ABS(F15),"0")&" hrs",IF(F15<0,"Behind "& TEXT(ABS(F15),"0")&" hrs","On Track"))
A16: Nagarjuna Reddy Sadhu | B16: Control Solutions | C16: Task | D16: =IFERROR(SUMIFS('Work Items'!N:N,'Work Items'!J:J,A16,'Work Items'!D:D,B16,'Work Items'!A:A,C16),0) | E16: =IFERROR(SUMIFS('Work Items'!O:O,'Work Items'!J:J,A16,'Work Items'!D:D,B16,'Work Items'!A:A,C16),0) | F16: =D16-E16 | G16: =IFERROR((D16-E16)/D16,0) | H16: =IF(F16>0,"Ahead "& TEXT(ABS(F16),"0")&" hrs",IF(F16<0,"Behind "& TEXT(ABS(F16),"0")&" hrs","On Track"))
... A33: Vishnudeep | B33: VRC Managed Services | C33: Task | D33: =IFERROR(SUMIFS('Work Items'!N:N,'Work Items'!J:J,A33,'Work Items'!D:D,B33,'Work Items'!A:A,C33),0) | E33: =IFERROR(SUMIFS('Work Items'!O:O,'Work Items'!J:J,A33,'Work Items'!D:D,B33,'Work Items'!A:A,C33),0) | F33: =D33-E33 | G33: =IFERROR((D33-E33)/D33,0) | H33: =IF(F33>0,"Ahead "& TEXT(ABS(F33),"0")&" hrs",IF(F33<0,"Behind "& TEXT(ABS(F33),"0")&" hrs","On Track"))
A35: TOTAL | D35: =SUM(D5:D33) | E35: =SUM(E5:E33) | F35: =SUM(F5:F33)

Sheet Risk Register
A1: OrbitFlow — Risk Register | All risks also in Work Items (Type=Risk)
A3: Risk Score = Probability × Impact · Critical ≥ 15 | High ≥ 10 | Medium ≥ 5 | Low < 5
A4: Type | B4: ID | C4: Project | D4: Risk Description | E4: Module | F4: SubModule | G4: Risk Category | H4: Assigned To | I4: Priority | J4: Status | K4: Risk Score | L4: Target Date | M4: Mitigation Hrs
